Traceback (most recent call last):
  File "/Users/feilong/miniconda3/envs/py/lib/python3.9/site-packages/jupyter_cache/executors/utils.py", line 58, in single_nb_execution
    executenb(
  File "/Users/feilong/miniconda3/envs/py/lib/python3.9/site-packages/nbclient/client.py", line 1112, in execute
    return NotebookClient(nb=nb, resources=resources, km=km, **kwargs).execute()
  File "/Users/feilong/miniconda3/envs/py/lib/python3.9/site-packages/nbclient/util.py", line 74, in wrapped
    return just_run(coro(*args, **kwargs))
  File "/Users/feilong/miniconda3/envs/py/lib/python3.9/site-packages/nbclient/util.py", line 53, in just_run
    return loop.run_until_complete(coro)
  File "/Users/feilong/miniconda3/envs/py/lib/python3.9/asyncio/base_events.py", line 642, in run_until_complete
    return future.result()
  File "/Users/feilong/miniconda3/envs/py/lib/python3.9/site-packages/nbclient/client.py", line 553, in async_execute
    await self.async_execute_cell(
  File "/Users/feilong/miniconda3/envs/py/lib/python3.9/site-packages/nbclient/client.py", line 857, in async_execute_cell
    self._check_raise_for_error(cell, exec_reply)
  File "/Users/feilong/miniconda3/envs/py/lib/python3.9/site-packages/nbclient/client.py", line 760, in _check_raise_for_error
    raise CellExecutionError.from_cell_and_msg(cell, exec_reply_content)
nbclient.exceptions.CellExecutionError: An error occurred while executing the following cell:
------------------
tmp_dir = '/dev/shm/forrest_tmp'
os.makedirs(tmp_dir, exist_ok=True)
------------------

[0;31m---------------------------------------------------------------------------[0m
[0;31mPermissionError[0m                           Traceback (most recent call last)
Cell [0;32mIn[2], line 2[0m
[1;32m      1[0m tmp_dir [38;5;241m=[39m [38;5;124m'[39m[38;5;124m/dev/shm/forrest_tmp[39m[38;5;124m'[39m
[0;32m----> 2[0m [43mos[49m[38;5;241;43m.[39;49m[43mmakedirs[49m[43m([49m[43mtmp_dir[49m[43m,[49m[43m [49m[43mexist_ok[49m[38;5;241;43m=[39;49m[38;5;28;43;01mTrue[39;49;00m[43m)[49m

File [0;32m~/miniconda3/envs/py/lib/python3.9/os.py:215[0m, in [0;36mmakedirs[0;34m(name, mode, exist_ok)[0m
[1;32m    213[0m [38;5;28;01mif[39;00m head [38;5;129;01mand[39;00m tail [38;5;129;01mand[39;00m [38;5;129;01mnot[39;00m path[38;5;241m.[39mexists(head):
[1;32m    214[0m     [38;5;28;01mtry[39;00m:
[0;32m--> 215[0m         [43mmakedirs[49m[43m([49m[43mhead[49m[43m,[49m[43m [49m[43mexist_ok[49m[38;5;241;43m=[39;49m[43mexist_ok[49m[43m)[49m
[1;32m    216[0m     [38;5;28;01mexcept[39;00m [38;5;167;01mFileExistsError[39;00m:
[1;32m    217[0m         [38;5;66;03m# Defeats race condition when another thread created the path[39;00m
[1;32m    218[0m         [38;5;28;01mpass[39;00m

File [0;32m~/miniconda3/envs/py/lib/python3.9/os.py:225[0m, in [0;36mmakedirs[0;34m(name, mode, exist_ok)[0m
[1;32m    223[0m         [38;5;28;01mreturn[39;00m
[1;32m    224[0m [38;5;28;01mtry[39;00m:
[0;32m--> 225[0m     [43mmkdir[49m[43m([49m[43mname[49m[43m,[49m[43m [49m[43mmode[49m[43m)[49m
[1;32m    226[0m [38;5;28;01mexcept[39;00m [38;5;167;01mOSError[39;00m:
[1;32m    227[0m     [38;5;66;03m# Cannot rely on checking for EEXIST, since the operating system[39;00m
[1;32m    228[0m     [38;5;66;03m# could give priority to other errors like EACCES or EROFS[39;00m
[1;32m    229[0m     [38;5;28;01mif[39;00m [38;5;129;01mnot[39;00m exist_ok [38;5;129;01mor[39;00m [38;5;129;01mnot[39;00m path[38;5;241m.[39misdir(name):

[0;31mPermissionError[0m: [Errno 1] Operation not permitted: '/dev/shm'
PermissionError: [Errno 1] Operation not permitted: '/dev/shm'

