Traceback (most recent call last):
  File "/Users/feilong/miniconda3/envs/py/lib/python3.9/site-packages/jupyter_cache/executors/utils.py", line 58, in single_nb_execution
    executenb(
  File "/Users/feilong/miniconda3/envs/py/lib/python3.9/site-packages/nbclient/client.py", line 1112, in execute
    return NotebookClient(nb=nb, resources=resources, km=km, **kwargs).execute()
  File "/Users/feilong/miniconda3/envs/py/lib/python3.9/site-packages/nbclient/util.py", line 74, in wrapped
    return just_run(coro(*args, **kwargs))
  File "/Users/feilong/miniconda3/envs/py/lib/python3.9/site-packages/nbclient/util.py", line 53, in just_run
    return loop.run_until_complete(coro)
  File "/Users/feilong/miniconda3/envs/py/lib/python3.9/asyncio/base_events.py", line 642, in run_until_complete
    return future.result()
  File "/Users/feilong/miniconda3/envs/py/lib/python3.9/site-packages/nbclient/client.py", line 553, in async_execute
    await self.async_execute_cell(
  File "/Users/feilong/miniconda3/envs/py/lib/python3.9/site-packages/nbclient/client.py", line 857, in async_execute_cell
    self._check_raise_for_error(cell, exec_reply)
  File "/Users/feilong/miniconda3/envs/py/lib/python3.9/site-packages/nbclient/client.py", line 760, in _check_raise_for_error
    raise CellExecutionError.from_cell_and_msg(cell, exec_reply_content)
nbclient.exceptions.CellExecutionError: An error occurred while executing the following cell:
------------------
mean, vmin, vmax
------------------

[0;31m---------------------------------------------------------------------------[0m
[0;31mNameError[0m                                 Traceback (most recent call last)
[0;32m<ipython-input-5-310954d1b690>[0m in [0;36m<module>[0;34m[0m
[0;32m----> 1[0;31m [0mmean[0m[0;34m,[0m [0mvmin[0m[0;34m,[0m [0mvmax[0m[0;34m[0m[0;34m[0m[0m
[0m
[0;31mNameError[0m: name 'mean' is not defined
NameError: name 'mean' is not defined

